<mujoco model="eb65">
  <compiler angle="radian" meshdir="/home/ros/eb65_ws/src/eb65_description/meshes/" balanceinertia="true" discardvisual="false"/>

  <default>
    <joint damping="0.01" armature="0.01" frictionloss="0.1"/>
  </default>

  <asset>
    <mesh name="001_simplified" file="001_simplified.stl" scale="0.001 0.001 0.001"/>
    <mesh name="002_simplified" file="002_simplified.stl" scale="0.001 0.001 0.001"/>
    <mesh name="003_simplified" file="003_simplified.stl" scale="0.001 0.001 0.001"/>
    <mesh name="004_simplified" file="004_simplified.stl" scale="0.001 0.001 0.001"/>
    <mesh name="005_simplified" file="005_simplified.stl" scale="0.001 0.001 0.001"/>
    <mesh name="006_simplified" file="006_simplified.stl" scale="0.001 0.001 0.001"/>
    <mesh name="007_simplified" file="007_simplified.stl" scale="0.001 0.001 0.001"/>
    <mesh name="008_simplified" file="008_simplified.stl" scale="0.001 0.001 0.001"/>
    <mesh name="009_simplified" file="009_simplified.stl" scale="0.001 0.001 0.001"/>
    <mesh name="010_simplified" file="010_simplified.stl" scale="0.001 0.001 0.001"/>
    <mesh name="011_simplified" file="011_simplified.stl" scale="0.001 0.001 0.001"/>
    <mesh name="012_simplified" file="012_simplified.stl" scale="0.001 0.001 0.001"/>
    <mesh name="013_simplified" file="013_simplified.stl" scale="0.001 0.001 0.001"/>
    <mesh name="014_simplified" file="014_simplified.stl" scale="0.001 0.001 0.001"/>
    <mesh name="015_simplified" file="015_simplified.stl" scale="0.001 0.001 0.001"/>
    <mesh name="016_simplified" file="016_simplified.stl" scale="0.001 0.001 0.001"/>
    <mesh name="017_simplified" file="017_simplified.stl" scale="0.001 0.001 0.001"/>
    <mesh name="018_simplified" file="018_simplified.stl" scale="0.001 0.001 0.001"/>
    <mesh name="019_simplified" file="019_simplified.stl" scale="0.001 0.001 0.001"/>
    <mesh name="020_simplified" file="020_simplified.stl" scale="0.001 0.001 0.001"/>
    <mesh name="021_simplified" file="021_simplified.stl" scale="0.001 0.001 0.001"/>
    <mesh name="022_simplified" file="022_simplified.stl" scale="0.001 0.001 0.001"/>
    <mesh name="023_simplified" file="023_simplified.stl" scale="0.001 0.001 0.001"/>
    <mesh name="024_simplified" file="024_simplified.stl" scale="0.001 0.001 0.001"/>
    <mesh name="025_simplified" file="025_simplified.stl" scale="0.001 0.001 0.001"/>
    <mesh name="026_simplified" file="026_simplified.stl" scale="0.001 0.001 0.001"/>
    <mesh name="027_simplified" file="027_simplified.stl" scale="0.001 0.001 0.001"/>
    <mesh name="028_simplified" file="028_simplified.stl" scale="0.001 0.001 0.001"/>
    <mesh name="029_simplified" file="029_simplified.stl" scale="0.001 0.001 0.001"/>
    <mesh name="031_simplified" file="031_simplified.stl" scale="0.001 0.001 0.001"/>
    <mesh name="030_simplified" file="030_simplified.stl" scale="0.001 0.001 0.001"/>
    <mesh name="032_simplified" file="032_simplified.stl" scale="0.001 0.001 0.001"/>
    <mesh name="034_simplified" file="034_simplified.stl" scale="0.001 0.001 0.001"/>
    <mesh name="035_simplified" file="035_simplified.stl" scale="0.001 0.001 0.001"/>
    <mesh name="033_simplified" file="033_simplified.stl" scale="0.001 0.001 0.001"/>
    <mesh name="036_simplified" file="036_simplified.stl" scale="0.001 0.001 0.001"/>
  </asset>

  <worldbody>
    <geom pos="-0.1 -0.1 0" quat="1 0 0 0" type="mesh" contype="0" conaffinity="0" group="1" density="0" rgba="0.2 0.2 0.8 1" mesh="001_simplified"/>
    <body name="base_rotation_link" pos="0 0 0.13">
      <inertial pos="0 -0.00171429 0" quat="0.707107 0.707107 0 0" mass="3.5" diaginertia="0.0228897 0.0228897 0.0175"/>
      <joint name="base_rotation_joint" pos="0 0 0" axis="0 0 1" range="-3.14 3.14" actuatorfrcrange="-10 10"/>
      <geom pos="0.1 -0.1 0" quat="-3.67321e-06 0 1 0" type="mesh" contype="0" conaffinity="0" group="1" density="0" mesh="002_simplified"/>
      <geom pos="0.1 -0.1 0" quat="0.707105 0 0 0.707108" type="mesh" contype="0" conaffinity="0" group="1" density="0" mesh="003_simplified"/>
      <geom pos="-0.09 -0.045 -0.02" quat="0.707105 0.707108 0 0" type="mesh" contype="0" conaffinity="0" group="1" density="0" rgba="0.2 0.2 0.8 1" mesh="004_simplified"/>
      <geom pos="0.11 0.045 -0.02" quat="0.000563087 0.000563089 0.707108 0.707105" type="mesh" contype="0" conaffinity="0" group="1" density="0" rgba="0.2 0.2 0.8 1" mesh="005_simplified"/>
      <body name="shoulder_right_link" pos="0.015 -0.045 0.1">
        <inertial pos="-0.00556962 0.0424937 0.0881646" quat="0.952339 0.0168089 -0.017466 -0.304077" mass="0.79" diaginertia="0.00846282 0.00761554 0.00194826"/>
        <joint name="shoulder_right_joint" pos="0 0 0" axis="0 1 0" range="-1.57 1.57" actuatorfrcrange="-5 5"/>
        <geom pos="0.1 0 -0.08" quat="0.000563087 0.000563089 0.707108 0.707105" type="mesh" contype="0" conaffinity="0" group="1" density="0" rgba="1 1 1 1" mesh="006_simplified"/>
        <geom pos="-0.1125 0.04 0.055" quat="0.707105 0.707108 0 0" type="mesh" contype="0" conaffinity="0" group="1" density="0" rgba="1 1 1 1" mesh="007_simplified"/>
        <geom pos="-0.1025 0.012 0.195" quat="0.707105 0.707108 0 0" type="mesh" contype="0" conaffinity="0" group="1" density="0" rgba="1 1 1 1" mesh="008_simplified"/>
        <geom pos="0.0875 0.145 0.235" quat="0.000563087 -0.707108 0.707105 0.000563089" type="mesh" contype="0" conaffinity="0" group="1" density="0" rgba="0.2 0.2 0.8 1" mesh="023_simplified"/>
        <geom pos="-0.1 0.09 -0.08" quat="0.707105 0.707108 0 0" type="mesh" contype="0" conaffinity="0" group="1" density="0" rgba="1 1 1 1" mesh="009_simplified"/>
        <geom pos="0.0875 0.05 0.055" quat="0.000563087 0.000563089 0.707108 0.707105" type="mesh" contype="0" conaffinity="0" group="1" density="0" rgba="1 1 1 1" mesh="010_simplified"/>
        <geom pos="0.0975 0.07 0.195" quat="0.000563087 0.000563089 0.707108 0.707105" type="mesh" contype="0" conaffinity="0" group="1" density="0" rgba="1 1 1 1" mesh="011_simplified"/>
        <geom pos="0.0855 -0.055 0.235" quat="0.707105 0 0 0.707108" type="mesh" contype="0" conaffinity="0" group="1" density="0" rgba="0.2 0.2 0.8 1" mesh="025_simplified"/>
        <geom pos="-0.1025 -0.035 0.23" quat="0.707105 0.707108 0 0" type="mesh" contype="0" conaffinity="0" group="1" density="0" rgba="0.2 0.2 0.8 1" mesh="036_simplified"/>
        <geom pos="-0.1025 0.12 0.43" quat="0.707105 -0.707108 0 0" type="mesh" contype="0" conaffinity="0" group="1" density="0" rgba="0.2 0.2 0.8 1" mesh="036_simplified"/>
        <geom pos="-0.1 0.048 -0.08" quat="0.707105 0.707108 0 0" type="mesh" contype="0" conaffinity="0" group="1" density="0" rgba="0.2 0.2 0.8 1" mesh="024_simplified"/>
        <geom pos="-0.1 0.117 0.095" quat="0.707105 -0.707108 0 0" type="mesh" contype="0" conaffinity="0" group="1" density="0" rgba="1 1 1 1" mesh="036_simplified"/>
        <geom pos="-0.1 -0.025 -0.105" quat="0.707105 0.707108 0 0" type="mesh" contype="0" conaffinity="0" group="1" density="0" rgba="1 1 1 1" mesh="036_simplified"/>
        <body name="elbow_link" pos="-0.0075 0.042 0.315">
          <inertial pos="0.05665 0 0.02085" quat="0.579957 0.404537 0.404537 0.579957" mass="0.2" diaginertia="0.000928789 0.000928789 0.0002"/>
          <joint name="elbow_joint" pos="0 0 0" axis="0 1 0" range="-1.57 1.57" actuatorfrcrange="-5 5"/>
          <geom pos="-0.09 0.04 -0.08" quat="0.707105 0.707108 0 0" type="mesh" contype="0" conaffinity="0" group="1" density="0" rgba="0.2 0.2 0.8 1" mesh="012_simplified"/>
          <geom pos="0.07 -0.1 -0.061" quat="0.499998 0.5 0.500002 0.5" type="mesh" contype="0" conaffinity="0" group="1" density="0" rgba="1 1 1 1" mesh="013_simplified"/>
          <body name="elbow_rotation_link" pos="0.13 0 0.047">
            <inertial pos="0.0443333 0 -0.00544444" quat="0 0.698908 0 0.715211" mass="0.45" diaginertia="0.00179123 0.00166631 0.000801285"/>
            <joint name="elbow_rotation_joint" pos="0 0 0" axis="1 0 0" range="-1.57 1.57" actuatorfrcrange="-5 5"/>
            <geom pos="0 -0.1 -0.1" quat="0.499998 0.5 0.500002 0.5" type="mesh" contype="0" conaffinity="0" group="1" density="0" rgba="1 1 1 1" mesh="014_simplified"/>
            <geom pos="0.18 -0.1 -0.045" quat="0.707105 0 0 0.707108" type="mesh" contype="0" conaffinity="0" group="1" density="0" rgba="1 1 1 1" mesh="015_simplified"/>
            <geom pos="0.185 -0.1 0.02" quat="0.707105 0 0 0.707108" type="mesh" contype="0" conaffinity="0" group="1" density="0" rgba="1 1 1 1" mesh="016_simplified"/>
            <geom pos="0.154 -0.1 -0.104" quat="0.499998 0.5 0.500002 0.5" type="mesh" contype="0" conaffinity="0" group="1" density="0" rgba="1 1 1 1" mesh="017_simplified"/>
            <geom pos="0.06 -0.034 -0.105" quat="0.707105 0.707108 0 0" type="mesh" contype="0" conaffinity="0" group="1" density="0" rgba="0.2 0.2 0.8 1" mesh="019_simplified"/>
            <geom pos="0.06 0.034 0.095" quat="0.707105 -0.707108 0 0" type="mesh" contype="0" conaffinity="0" group="1" density="0" rgba="0.2 0.2 0.8 1" mesh="020_simplified"/>
            <geom pos="-0.06 -0.035 -0.105" quat="0.707105 0.707108 0 0" type="mesh" contype="0" conaffinity="0" group="1" density="0" rgba="0.2 0.2 0.8 1" mesh="021_simplified"/>
            <geom pos="0.14 0.035 -0.105" quat="0.000563087 0.000563089 0.707108 0.707105" type="mesh" contype="0" conaffinity="0" group="1" density="0" rgba="0.2 0.2 0.8 1" mesh="022_simplified"/>
            <body name="wrist_link" pos="0.204 -0.003 -0.006">
              <inertial pos="0.02 0 0" mass="0.2" diaginertia="0.0002 0.0002 0.0002"/>
              <joint name="wrist_joint" pos="0 0 0" axis="0 1 0" range="-1.57 1.57" actuatorfrcrange="-5 5"/>
              <geom pos="0.1 -0.03 -0.1" quat="0.000563087 0.000563089 0.707108 0.707105" type="mesh" contype="0" conaffinity="0" group="1" density="0" rgba="0.2 0.2 0.8 1" mesh="018_simplified"/>
              <body name="gripper_rotation_link" pos="0.04 0 -0.005">
                <inertial pos="0.0392857 0.00285714 0" quat="0.448298 0.448298 0.546835 0.546835" mass="0.35" diaginertia="0.000405714 0.000405714 0.00035"/>
                <joint name="gear_joint" pos="0 0 0" axis="1 0 0" range="-1.57 1.57" actuatorfrcrange="-5 5"/>
                <geom pos="0 -0.097 0.1" quat="0.707105 0 0.707108 0" type="mesh" contype="0" conaffinity="0" group="1" density="0" rgba="1 1 1 1" mesh="026_simplified"/>
                <geom pos="0.05 -0.095 0.1" quat="0.499998 -0.5 -0.500002 0.5" type="mesh" contype="0" conaffinity="0" group="1" density="0" rgba="1 1 1 1" mesh="027_simplified"/>
                <geom pos="0.05 0.105 0.1" quat="0.499998 -0.5 0.500002 -0.5" type="mesh" contype="0" conaffinity="0" group="1" density="0" rgba="1 1 1 1" mesh="028_simplified"/>
                <body name="gear_link" pos="0.058 0.005 0">
                  <inertial pos="0 0 0" mass="0.1" diaginertia="0.0001 0.0001 0.0001"/>
                  <joint name="gripper_joint" pos="0 0 0" axis="1 0 0" range="-0.55 0.8" actuatorfrcrange="-2 2"/>
                  <geom pos="0 -0.1 0.1" quat="0.707105 0 0.707108 0" type="mesh" contype="0" conaffinity="0" group="1" density="0" rgba="0.2 0.2 0.8 1" mesh="030_simplified"/>
                </body>
                <body name="bottom_finger" pos="0.065 0.005 -0.013">
                  <inertial pos="0.00388889 0.0111111 0.00694444" quat="0.372259 0.392413 -0.778287 0.318912" mass="0.18" diaginertia="0.000210025 0.000207694 0.000182331"/>
                  <joint name="bottom_prismatic" pos="0 0 0" axis="0 1 0" type="slide" range="-0.016 0.016" actuatorfrcrange="-2 2"/>
                  <geom pos="0 -0.1 0.1" quat="0.499998 -0.5 -0.500002 0.5" type="mesh" contype="0" conaffinity="0" group="1" density="0" rgba="0.2 0.2 0.8 1" mesh="029_simplified"/>
                  <geom pos="0.002 0.12 0.11" quat="0.499998 -0.5 0.500002 -0.5" type="mesh" contype="0" conaffinity="0" group="1" density="0" rgba="0.2 0.2 0.8 1" mesh="032_simplified"/>
                  <geom pos="0.012 0.12 0.115" quat="0.499998 -0.5 0.500002 -0.5" type="mesh" contype="0" conaffinity="0" group="1" density="0" rgba="0.2 0.2 0.8 1" mesh="034_simplified"/>
                </body>
                <body name="top_finger" pos="0.065 0.005 0.013">
                  <inertial pos="0.00388889 -0.0111111 -0.00625" quat="0.298034 0.72202 -0.462825 0.419114" mass="0.18" diaginertia="0.000208237 0.000206038 0.000182199"/>
                  <joint name="top_prismatic" pos="0 0 0" axis="0 -1 0" type="slide" range="-0.016 0.016" actuatorfrcrange="-2 2"/>
                  <geom pos="0 -0.1 0.1" quat="0.499998 -0.5 -0.500002 0.5" type="mesh" contype="0" conaffinity="0" group="1" density="0" rgba="0.2 0.2 0.8 1" mesh="031_simplified"/>
                  <geom pos="0.002 0.08 0.09" quat="0.499998 -0.5 0.500002 -0.5" type="mesh" contype="0" conaffinity="0" group="1" density="0" rgba="0.2 0.2 0.8 1" mesh="035_simplified"/>
                  <geom pos="0.012 0.08 0.0875" quat="0.499998 -0.5 0.500002 -0.5" type="mesh" contype="0" conaffinity="0" group="1" density="0" rgba="0.2 0.2 0.8 1" mesh="033_simplified"/>
                </body>
              </body>
            </body>
          </body>
        </body>
      </body>
    </body>
  </worldbody>

  <actuator>
    <position name="base_rotation_actuator" joint="base_rotation_joint" ctrlrange="-3.14 3.14" ctrllimited="true" kp="100" kv="10"/>
    <position name="shoulder_right_actuator" joint="shoulder_right_joint" ctrlrange="-1.5 1.57" ctrllimited="true" kp="100" kv="10"/>
    <position name="elbow_actuator" joint="elbow_joint" ctrlrange="-1.5 1.5" ctrllimited="true" kp="50" kv="5"/>
    <position name="elbow_rotation_actuator" joint="elbow_rotation_joint" ctrlrange="-3.14 3.14" ctrllimited="true" kp="30" kv="3"/>
    <position name="wrist_actuator" joint="wrist_joint" ctrlrange="-1.0472 1.0472" ctrllimited="true" kp="20" kv="2"/>
    <position name="gripper_actuator" joint="gripper_joint" ctrlrange="-0.55 0.8" ctrllimited="true" kp="10" kv="1"/>
  </actuator>
</mujoco>
