<?xml version="1.0" ?>
<!-- =================================================================================== -->
<!-- |    This document was autogenerated by xacro from /home/ros/eb65_ws/install/eb65_description/share/eb65_description/model/eb65.urdf | -->
<!-- |    EDITING THIS FILE BY HAND IS NOT RECOMMENDED                                 | -->
<!-- =================================================================================== -->
<robot name="eb65">
  <material name="blue">
    <color rgba="0.2 0.2 0.8 1"/>
  </material>
  <material name="gray">
    <color rgba="0.5 0.5 0.5 1"/>
  </material>
  <material name="white">
    <color rgba="1 1 1 1"/>
  </material>
  <!-- ==================== BASE GROUP ==================== -->
  <link name="base_footprint">
    <inertial>
      <origin rpy="0 0 0" xyz="0 0 0"/>
      <mass value="0.001"/>
      <inertia ixx="1e-6" ixy="0" ixz="0" iyy="1e-6" iyz="0" izz="1e-6"/>
    </inertial>
  </link>
  <link name="base_link">
    <visual>
      <origin rpy="0.0 0.0 0.0" xyz="-0.1 -0.1 0.0"/>
      <geometry>
        <mesh filename="file:///home/ros/eb65_ws/src/eb65_description/meshes/001_simplified.stl" scale="0.001 0.001 0.001"/>
      </geometry>
      <material name="blue"/>
    </visual>
    <collision>
      <origin rpy="0.0 0.0 0.0" xyz="-0.1 -0.1 0.0"/>
      <geometry>
        <mesh filename="file:///home/ros/eb65_ws/src/eb65_description/meshes/001_simplified.stl" scale="0.001 0.001 0.001"/>
      </geometry>
    </collision>
    <inertial>
      <origin rpy="0 0 0" xyz="0 0 0.065"/>
      <mass value="4.0"/>
      <inertia ixx="0.03" ixy="0" ixz="0" iyy="0.03" iyz="0" izz="0.03"/>
    </inertial>
  </link>
  <link name="base_rotation_link">
    <visual>
      <origin rpy="0.0 3.1416 0.0" xyz="0.1 -0.1 0.0"/>
      <geometry>
        <mesh filename="file:///home/ros/eb65_ws/src/eb65_description/meshes/002_simplified.stl" scale="0.001 0.001 0.001"/>
      </geometry>
    </visual>
    <collision>
      <origin rpy="0.0 3.1416 0.0" xyz="0.1 -0.1 0.0"/>
      <geometry>
        <mesh filename="file:///home/ros/eb65_ws/src/eb65_description/meshes/002_simplified.stl" scale="0.001 0.001 0.001"/>
      </geometry>
    </collision>
    <inertial>
      <origin rpy="0 0 0" xyz="0 0 0"/>
      <mass value="1.0"/>
      <inertia ixx="0.005" ixy="0" ixz="0" iyy="0.005" iyz="0" izz="0.005"/>
    </inertial>
  </link>
  <link name="base_link_3">
    <visual>
      <origin rpy="0.0 0.0 1.5708" xyz="0.1 -0.1 0.0"/>
      <geometry>
        <mesh filename="file:///home/ros/eb65_ws/src/eb65_description/meshes/003_simplified.stl" scale="0.001 0.001 0.001"/>
      </geometry>
      <material name="gray"/>
    </visual>
    <collision>
      <origin rpy="0.0 0.0 1.5708" xyz="0.1 -0.1 0.0"/>
      <geometry>
        <mesh filename="file:///home/ros/eb65_ws/src/eb65_description/meshes/003_simplified.stl" scale="0.001 0.001 0.001"/>
      </geometry>
    </collision>
    <inertial>
      <origin rpy="0 0 0" xyz="0 0 0"/>
      <mass value="1.0"/>
      <inertia ixx="0.005" ixy="0" ixz="0" iyy="0.005" iyz="0" izz="0.005"/>
    </inertial>
  </link>
  <link name="base_link_4">
    <visual>
      <origin rpy="1.5708 0.0 0.0" xyz="-0.09 0.015 -0.02"/>
      <geometry>
        <mesh filename="file:///home/ros/eb65_ws/src/eb65_description/meshes/004_simplified.stl" scale="0.001 0.001 0.001"/>
      </geometry>
      <material name="blue"/>
    </visual>
    <collision>
      <origin rpy="1.5708 0.0 0.0" xyz="-0.09 0.015 -0.02"/>
      <geometry>
        <mesh filename="file:///home/ros/eb65_ws/src/eb65_description/meshes/004_simplified.stl" scale="0.001 0.001 0.001"/>
      </geometry>
    </collision>
    <inertial>
      <origin rpy="0 0 0" xyz="0 0 0"/>
      <mass value="0.8"/>
      <inertia ixx="0.004" ixy="0" ixz="0" iyy="0.004" iyz="0" izz="0.004"/>
    </inertial>
  </link>
  <link name="base_link_5">
    <visual>
      <origin rpy="1.5708 0.0 3.14" xyz="0.11 -0.015 -0.02"/>
      <geometry>
        <mesh filename="file:///home/ros/eb65_ws/src/eb65_description/meshes/005_simplified.stl" scale="0.001 0.001 0.001"/>
      </geometry>
      <material name="blue"/>
    </visual>
    <collision>
      <origin rpy="1.5708 0.0 3.14" xyz="0.11 -0.015 -0.02"/>
      <geometry>
        <mesh filename="file:///home/ros/eb65_ws/src/eb65_description/meshes/005_simplified.stl" scale="0.001 0.001 0.001"/>
      </geometry>
    </collision>
    <inertial>
      <origin rpy="0 0 0" xyz="0 0 0"/>
      <mass value="0.7"/>
      <inertia ixx="0.0035" ixy="0" ixz="0" iyy="0.0035" iyz="0" izz="0.0035"/>
    </inertial>
  </link>
  <!-- ==================== RIGHT SHOULDER GROUP ==================== -->
  <link name="shoulder_right_link">
    <visual>
      <origin rpy="1.5708 0.0 3.14" xyz="0.1 0.0 -0.08"/>
      <geometry>
        <mesh filename="file:///home/ros/eb65_ws/src/eb65_description/meshes/006_simplified.stl" scale="0.001 0.001 0.001"/>
      </geometry>
      <material name="white"/>
    </visual>
    <collision>
      <origin rpy="1.5708 0.0 3.14" xyz="0.1 0.0 -0.08"/>
      <geometry>
        <mesh filename="file:///home/ros/eb65_ws/src/eb65_description/meshes/006_simplified.stl" scale="0.001 0.001 0.001"/>
      </geometry>
    </collision>
    <inertial>
      <origin rpy="0 0 0" xyz="-0.0375 0.012 0.018"/>
      <mass value="0.15"/>
      <inertia ixx="0.00015" ixy="0" ixz="0" iyy="0.00015" iyz="0" izz="0.00015"/>
    </inertial>
  </link>
  <link name="shoulder_right_link_1">
    <visual>
      <origin rpy="1.5708 0.0 0.0" xyz="-0.1 0.02 -0.04"/>
      <geometry>
        <mesh filename="file:///home/ros/eb65_ws/src/eb65_description/meshes/007_simplified.stl" scale="0.001 0.001 0.001"/>
      </geometry>
      <material name="white"/>
    </visual>
    <collision>
      <origin rpy="1.5708 0.0 0.0" xyz="-0.1 0.02 -0.04"/>
      <geometry>
        <mesh filename="file:///home/ros/eb65_ws/src/eb65_description/meshes/007_simplified.stl" scale="0.001 0.001 0.001"/>
      </geometry>
    </collision>
    <inertial>
      <origin rpy="0 0 0" xyz="0 0 0"/>
      <mass value="0.075"/>
      <inertia ixx="7.5e-5" ixy="0" ixz="0" iyy="7.5e-5" iyz="0" izz="7.5e-5"/>
    </inertial>
  </link>
  <link name="shoulder_right_link_2">
    <visual>
      <origin rpy="1.5708 0.0 0.0" xyz="-0.09 0.0 0.0"/>
      <geometry>
        <mesh filename="file:///home/ros/eb65_ws/src/eb65_description/meshes/008_simplified.stl" scale="0.001 0.001 0.001"/>
      </geometry>
      <material name="white"/>
    </visual>
    <collision>
      <origin rpy="1.5708 0.0 0.0" xyz="-0.09 0.0 0.0"/>
      <geometry>
        <mesh filename="file:///home/ros/eb65_ws/src/eb65_description/meshes/008_simplified.stl" scale="0.001 0.001 0.001"/>
      </geometry>
    </collision>
    <inertial>
      <origin rpy="0 0 0" xyz="0 0 0"/>
      <mass value="0.075"/>
      <inertia ixx="7.5e-5" ixy="0" ixz="0" iyy="7.5e-5" iyz="0" izz="7.5e-5"/>
    </inertial>
  </link>
  <!-- ==================== LEFT SHOULDER GROUP ==================== -->
  <link name="shoulder_left_link">
    <visual>
      <origin rpy="1.5708 0.0 0.0" xyz="-0.1 0.0 -0.08"/>
      <geometry>
        <mesh filename="file:///home/ros/eb65_ws/src/eb65_description/meshes/009_simplified.stl" scale="0.001 0.001 0.001"/>
      </geometry>
      <material name="white"/>
    </visual>
    <collision>
      <origin rpy="1.5708 0.0 0.0" xyz="-0.1 0.0 -0.08"/>
      <geometry>
        <mesh filename="file:///home/ros/eb65_ws/src/eb65_description/meshes/009_simplified.stl" scale="0.001 0.001 0.001"/>
      </geometry>
    </collision>
    <inertial>
      <origin rpy="0 0 0" xyz="0.0375 -0.012 0.018"/>
      <mass value="0.15"/>
      <inertia ixx="0.00015" ixy="0" ixz="0" iyy="0.00015" iyz="0" izz="0.00015"/>
    </inertial>
  </link>
  <link name="shoulder_left_link_1">
    <visual>
      <origin rpy="1.5708 0.0 3.14" xyz="0.1 0.0 -0.04"/>
      <geometry>
        <mesh filename="file:///home/ros/eb65_ws/src/eb65_description/meshes/010_simplified.stl" scale="0.001 0.001 0.001"/>
      </geometry>
      <material name="white"/>
    </visual>
    <collision>
      <origin rpy="1.5708 0.0 3.14" xyz="0.1 0.0 -0.04"/>
      <geometry>
        <mesh filename="file:///home/ros/eb65_ws/src/eb65_description/meshes/010_simplified.stl" scale="0.001 0.001 0.001"/>
      </geometry>
    </collision>
    <inertial>
      <origin rpy="0 0 0" xyz="0 0 0"/>
      <mass value="0.075"/>
      <inertia ixx="7.5e-5" ixy="0" ixz="0" iyy="7.5e-5" iyz="0" izz="7.5e-5"/>
    </inertial>
  </link>
  <link name="shoulder_left_link_2">
    <visual>
      <origin rpy="1.5708 0.0 3.14" xyz="0.1 0.0 0.0"/>
      <geometry>
        <mesh filename="file:///home/ros/eb65_ws/src/eb65_description/meshes/011_simplified.stl" scale="0.001 0.001 0.001"/>
      </geometry>
      <material name="white"/>
    </visual>
    <collision>
      <origin rpy="1.5708 0.0 3.14" xyz="0.1 0.0 0.0"/>
      <geometry>
        <mesh filename="file:///home/ros/eb65_ws/src/eb65_description/meshes/011_simplified.stl" scale="0.001 0.001 0.001"/>
      </geometry>
    </collision>
    <inertial>
      <origin rpy="0 0 0" xyz="0 0 0"/>
      <mass value="0.075"/>
      <inertia ixx="7.5e-5" ixy="0" ixz="0" iyy="7.5e-5" iyz="0" izz="7.5e-5"/>
    </inertial>
  </link>
  <!-- ==================== ELBOW GROUP ==================== -->
  <link name="elbow_link">
    <visual>
      <origin rpy="1.5708 0.0 0.0" xyz="-0.09 0.04 -0.08"/>
      <geometry>
        <mesh filename="file:///home/ros/eb65_ws/src/eb65_description/meshes/012_simplified.stl" scale="0.001 0.001 0.001"/>
      </geometry>
      <material name="blue"/>
    </visual>
    <collision>
      <origin rpy="1.5708 0.0 0.0" xyz="-0.09 0.04 -0.08"/>
      <geometry>
        <mesh filename="file:///home/ros/eb65_ws/src/eb65_description/meshes/012_simplified.stl" scale="0.001 0.001 0.001"/>
      </geometry>
    </collision>
    <inertial>
      <origin rpy="0 0 0" xyz="0 0 0"/>
      <mass value="0.1"/>
      <inertia ixx="0.0001" ixy="0" ixz="0" iyy="0.0001" iyz="0" izz="0.0001"/>
    </inertial>
  </link>
  <link name="elbow_support_link">
    <visual>
      <origin rpy="1.5708 0.0 1.5708" xyz="0.0 -0.1 -0.1"/>
      <geometry>
        <mesh filename="file:///home/ros/eb65_ws/src/eb65_description/meshes/013_simplified.stl" scale="0.001 0.001 0.001"/>
      </geometry>
      <material name="white"/>
    </visual>
    <collision>
      <origin rpy="1.5708 0.0 1.5708" xyz="0.0 -0.1 -0.1"/>
      <geometry>
        <mesh filename="file:///home/ros/eb65_ws/src/eb65_description/meshes/013_simplified.stl" scale="0.001 0.001 0.001"/>
      </geometry>
    </collision>
    <inertial>
      <origin rpy="0 0 0" xyz="0.0433 0 0.0027"/>
      <mass value="0.1"/>
      <inertia ixx="0.0001" ixy="0" ixz="0" iyy="0.0001" iyz="0" izz="0.0001"/>
    </inertial>
  </link>
  <link name="elbow_rotation_link">
    <visual>
      <origin rpy="1.5708 0.0 1.5708" xyz="0.0 -0.1 -0.1"/>
      <geometry>
        <mesh filename="file:///home/ros/eb65_ws/src/eb65_description/meshes/014_simplified.stl" scale="0.001 0.001 0.001"/>
      </geometry>
      <material name="white"/>
    </visual>
    <collision>
      <origin rpy="1.5708 0.0 1.5708" xyz="0.0 -0.1 -0.1"/>
      <geometry>
        <mesh filename="file:///home/ros/eb65_ws/src/eb65_description/meshes/014_simplified.stl" scale="0.001 0.001 0.001"/>
      </geometry>
    </collision>
    <inertial>
      <origin rpy="0 0 0" xyz="0 0 0"/>
      <mass value="0.1"/>
      <inertia ixx="0.0001" ixy="0" ixz="0" iyy="0.0001" iyz="0" izz="0.0001"/>
    </inertial>
  </link>
  <!-- ==================== WRIST GROUP ==================== -->
  <link name="support_link_1">
    <visual>
      <origin rpy="0.0 0.0 1.5708" xyz="0.18 -0.1 0.0"/>
      <geometry>
        <mesh filename="file:///home/ros/eb65_ws/src/eb65_description/meshes/015_simplified.stl" scale="0.001 0.001 0.001"/>
      </geometry>
      <material name="white"/>
    </visual>
    <collision>
      <origin rpy="0.0 0.0 1.5708" xyz="0.18 -0.1 0.0"/>
      <geometry>
        <mesh filename="file:///home/ros/eb65_ws/src/eb65_description/meshes/015_simplified.stl" scale="0.001 0.001 0.001"/>
      </geometry>
    </collision>
    <inertial>
      <origin rpy="0 0 0" xyz="0 0 0"/>
      <mass value="0.05"/>
      <inertia ixx="5e-5" ixy="0" ixz="0" iyy="5e-5" iyz="0" izz="5e-5"/>
    </inertial>
  </link>
  <link name="support_link_2">
    <visual>
      <origin rpy="0.0 0.0 1.5708" xyz="0.18 -0.1 0.0"/>
      <geometry>
        <mesh filename="file:///home/ros/eb65_ws/src/eb65_description/meshes/016_simplified.stl" scale="0.001 0.001 0.001"/>
      </geometry>
      <material name="white"/>
    </visual>
    <collision>
      <origin rpy="0.0 0.0 1.5708" xyz="0.18 -0.1 0.0"/>
      <geometry>
        <mesh filename="file:///home/ros/eb65_ws/src/eb65_description/meshes/016_simplified.stl" scale="0.001 0.001 0.001"/>
      </geometry>
    </collision>
    <inertial>
      <origin rpy="0 0 0" xyz="0 0 0"/>
      <mass value="0.05"/>
      <inertia ixx="5e-5" ixy="0" ixz="0" iyy="5e-5" iyz="0" izz="5e-5"/>
    </inertial>
  </link>
  <link name="support_link_3">
    <visual>
      <origin rpy="1.5708 0.0 1.5708" xyz="0.0 -0.1 -0.1"/>
      <geometry>
        <mesh filename="file:///home/ros/eb65_ws/src/eb65_description/meshes/017_simplified.stl" scale="0.001 0.001 0.001"/>
      </geometry>
      <material name="white"/>
    </visual>
    <collision>
      <origin rpy="1.5708 0.0 1.5708" xyz="0.0 -0.1 -0.1"/>
      <geometry>
        <mesh filename="file:///home/ros/eb65_ws/src/eb65_description/meshes/017_simplified.stl" scale="0.001 0.001 0.001"/>
      </geometry>
    </collision>
    <inertial>
      <origin rpy="0 0 0" xyz="0 0 0"/>
      <mass value="0.05"/>
      <inertia ixx="5e-5" ixy="0" ixz="0" iyy="5e-5" iyz="0" izz="5e-5"/>
    </inertial>
  </link>
  <link name="wrist_link">
    <visual>
      <origin rpy="1.5708 0.0 3.14" xyz="0.1 -0.03 -0.1"/>
      <geometry>
        <mesh filename="file:///home/ros/eb65_ws/src/eb65_description/meshes/018_simplified.stl" scale="0.001 0.001 0.001"/>
      </geometry>
      <material name="blue"/>
    </visual>
    <collision>
      <origin rpy="1.5708 0.0 3.14" xyz="0.1 -0.03 -0.1"/>
      <geometry>
        <mesh filename="file:///home/ros/eb65_ws/src/eb65_description/meshes/018_simplified.stl" scale="0.001 0.001 0.001"/>
      </geometry>
    </collision>
    <inertial>
      <origin rpy="0 0 0" xyz="0.02 0 0"/>
      <mass value="0.2"/>
      <inertia ixx="0.0002" ixy="0" ixz="0" iyy="0.0002" iyz="0" izz="0.0002"/>
    </inertial>
  </link>
  <link name="support_link_4">
    <visual>
      <origin rpy="1.5708 0.0 0.0" xyz="-0.02 0.0 -0.1"/>
      <geometry>
        <mesh filename="file:///home/ros/eb65_ws/src/eb65_description/meshes/019_simplified.stl" scale="0.001 0.001 0.001"/>
      </geometry>
      <material name="blue"/>
    </visual>
    <collision>
      <origin rpy="1.5708 0.0 0.0" xyz="-0.02 0.0 -0.1"/>
      <geometry>
        <mesh filename="file:///home/ros/eb65_ws/src/eb65_description/meshes/019_simplified.stl" scale="0.001 0.001 0.001"/>
      </geometry>
    </collision>
    <inertial>
      <origin rpy="0 0 0" xyz="0 0 0"/>
      <mass value="0.05"/>
      <inertia ixx="5e-5" ixy="0" ixz="0" iyy="5e-5" iyz="0" izz="5e-5"/>
    </inertial>
  </link>
  <link name="support_link_5">
    <visual>
      <origin rpy="-1.5708 0.0 0.0" xyz="-0.02 0.0 0.1"/>
      <geometry>
        <mesh filename="file:///home/ros/eb65_ws/src/eb65_description/meshes/020_simplified.stl" scale="0.001 0.001 0.001"/>
      </geometry>
      <material name="blue"/>
    </visual>
    <collision>
      <origin rpy="-1.5708 0.0 0.0" xyz="-0.02 0.0 0.1"/>
      <geometry>
        <mesh filename="file:///home/ros/eb65_ws/src/eb65_description/meshes/020_simplified.stl" scale="0.001 0.001 0.001"/>
      </geometry>
    </collision>
    <inertial>
      <origin rpy="0 0 0" xyz="0 0 0"/>
      <mass value="0.05"/>
      <inertia ixx="5e-5" ixy="0" ixz="0" iyy="5e-5" iyz="0" izz="5e-5"/>
    </inertial>
  </link>
  <link name="support_link_6">
    <visual>
      <origin rpy="1.5708 0.0 0.0" xyz="-0.1 0.0 -0.1"/>
      <geometry>
        <mesh filename="file:///home/ros/eb65_ws/src/eb65_description/meshes/021_simplified.stl" scale="0.001 0.001 0.001"/>
      </geometry>
      <material name="blue"/>
    </visual>
    <collision>
      <origin rpy="1.5708 0.0 0.0" xyz="-0.1 0.0 -0.1"/>
      <geometry>
        <mesh filename="file:///home/ros/eb65_ws/src/eb65_description/meshes/021_simplified.stl" scale="0.001 0.001 0.001"/>
      </geometry>
    </collision>
    <inertial>
      <origin rpy="0 0 0" xyz="0 0 0"/>
      <mass value="0.05"/>
      <inertia ixx="5e-5" ixy="0" ixz="0" iyy="5e-5" iyz="0" izz="5e-5"/>
    </inertial>
  </link>
  <link name="support_link_7">
    <visual>
      <origin rpy="1.5708 0.0 3.14" xyz="0.1 0.0 -0.1"/>
      <geometry>
        <mesh filename="file:///home/ros/eb65_ws/src/eb65_description/meshes/022_simplified.stl" scale="0.001 0.001 0.001"/>
      </geometry>
      <material name="blue"/>
    </visual>
    <collision>
      <origin rpy="1.5708 0.0 3.14" xyz="0.1 0.0 -0.1"/>
      <geometry>
        <mesh filename="file:///home/ros/eb65_ws/src/eb65_description/meshes/022_simplified.stl" scale="0.001 0.001 0.001"/>
      </geometry>
    </collision>
    <inertial>
      <origin rpy="0 0 0" xyz="0 0 0"/>
      <mass value="0.05"/>
      <inertia ixx="5e-5" ixy="0" ixz="0" iyy="5e-5" iyz="0" izz="5e-5"/>
    </inertial>
  </link>
  <link name="support_link_8">
    <visual>
      <origin rpy="0.0 3.14 1.5708" xyz="0.1 0.1 0.13"/>
      <geometry>
        <mesh filename="file:///home/ros/eb65_ws/src/eb65_description/meshes/023_simplified.stl" scale="0.001 0.001 0.001"/>
      </geometry>
      <material name="blue"/>
    </visual>
    <collision>
      <origin rpy="0.0 3.14 1.5708" xyz="0.1 0.1 0.13"/>
      <geometry>
        <mesh filename="file:///home/ros/eb65_ws/src/eb65_description/meshes/023_simplified.stl" scale="0.001 0.001 0.001"/>
      </geometry>
    </collision>
    <inertial>
      <origin rpy="0 0 0" xyz="0 0 0"/>
      <mass value="0.05"/>
      <inertia ixx="5e-5" ixy="0" ixz="0" iyy="5e-5" iyz="0" izz="5e-5"/>
    </inertial>
  </link>
  <link name="support_link_9">
    <visual>
      <origin rpy="1.5708 0.0 0.0" xyz="-0.1 0.0 -0.025"/>
      <geometry>
        <mesh filename="file:///home/ros/eb65_ws/src/eb65_description/meshes/024_simplified.stl" scale="0.001 0.001 0.001"/>
      </geometry>
      <material name="blue"/>
    </visual>
    <collision>
      <origin rpy="1.5708 0.0 0.0" xyz="-0.1 0.0 -0.025"/>
      <geometry>
        <mesh filename="file:///home/ros/eb65_ws/src/eb65_description/meshes/024_simplified.stl" scale="0.001 0.001 0.001"/>
      </geometry>
    </collision>
    <inertial>
      <origin rpy="0 0 0" xyz="0 0 0"/>
      <mass value="0.05"/>
      <inertia ixx="5e-5" ixy="0" ixz="0" iyy="5e-5" iyz="0" izz="5e-5"/>
    </inertial>
  </link>
  <link name="support_link_10">
    <visual>
      <origin rpy="0.0 0.0 1.5708" xyz="0.1 -0.1 0.0"/>
      <geometry>
        <mesh filename="file:///home/ros/eb65_ws/src/eb65_description/meshes/025_simplified.stl" scale="0.001 0.001 0.001"/>
      </geometry>
      <material name="blue"/>
    </visual>
    <collision>
      <origin rpy="0.0 0.0 1.5708" xyz="0.1 -0.1 0.0"/>
      <geometry>
        <mesh filename="file:///home/ros/eb65_ws/src/eb65_description/meshes/025_simplified.stl" scale="0.001 0.001 0.001"/>
      </geometry>
    </collision>
    <inertial>
      <origin rpy="0 0 0" xyz="0 0 0"/>
      <mass value="0.05"/>
      <inertia ixx="5e-5" ixy="0" ixz="0" iyy="5e-5" iyz="0" izz="5e-5"/>
    </inertial>
  </link>
  <!-- ==================== GRIPPER GROUP ==================== -->
  <link name="gripper_rotation_link">
    <visual>
      <origin rpy="0.0 1.5708 0.0" xyz="0.0 -0.097 0.1"/>
      <geometry>
        <mesh filename="file:///home/ros/eb65_ws/src/eb65_description/meshes/026_simplified.stl" scale="0.001 0.001 0.001"/>
      </geometry>
      <material name="white"/>
    </visual>
    <collision>
      <origin rpy="0.0 1.5708 0.0" xyz="0.0 -0.097 0.1"/>
      <geometry>
        <mesh filename="file:///home/ros/eb65_ws/src/eb65_description/meshes/026_simplified.stl" scale="0.001 0.001 0.001"/>
      </geometry>
    </collision>
    <inertial>
      <origin rpy="0 0 0" xyz="0.025 0 0"/>
      <mass value="0.15"/>
      <inertia ixx="0.00015" ixy="0" ixz="0" iyy="0.00015" iyz="0" izz="0.00015"/>
    </inertial>
  </link>
  <link name="gripper_support_link">
    <visual>
      <origin rpy="-1.5708 0.0 1.5708" xyz="0.0 -0.1 0.1"/>
      <geometry>
        <mesh filename="file:///home/ros/eb65_ws/src/eb65_description/meshes/027_simplified.stl" scale="0.001 0.001 0.001"/>
      </geometry>
      <material name="white"/>
    </visual>
    <collision>
      <origin rpy="-1.5708 0.0 1.5708" xyz="0.0 -0.1 0.1"/>
      <geometry>
        <mesh filename="file:///home/ros/eb65_ws/src/eb65_description/meshes/027_simplified.stl" scale="0.001 0.001 0.001"/>
      </geometry>
    </collision>
    <inertial>
      <origin rpy="0 0 0" xyz="0 0 0"/>
      <mass value="0.1"/>
      <inertia ixx="0.0001" ixy="0" ixz="0" iyy="0.0001" iyz="0" izz="0.0001"/>
    </inertial>
  </link>
  <link name="gripper_support_link_2">
    <visual>
      <origin rpy="-1.5708 0.0 -1.5708" xyz="0.0 0.1 0.1"/>
      <geometry>
        <mesh filename="file:///home/ros/eb65_ws/src/eb65_description/meshes/028_simplified.stl" scale="0.001 0.001 0.001"/>
      </geometry>
      <material name="white"/>
    </visual>
    <collision>
      <origin rpy="-1.5708 0.0 -1.5708" xyz="0.0 0.1 0.1"/>
      <geometry>
        <mesh filename="file:///home/ros/eb65_ws/src/eb65_description/meshes/028_simplified.stl" scale="0.001 0.001 0.001"/>
      </geometry>
    </collision>
    <inertial>
      <origin rpy="0 0 0" xyz="0 0 0"/>
      <mass value="0.1"/>
      <inertia ixx="0.0001" ixy="0" ixz="0" iyy="0.0001" iyz="0" izz="0.0001"/>
    </inertial>
  </link>
  <link name="bottom_finger">
    <visual>
      <origin rpy="-1.5708 0.0 1.5708" xyz="0.0 -0.1 0.1"/>
      <geometry>
        <mesh filename="file:///home/ros/eb65_ws/src/eb65_description/meshes/029_simplified.stl" scale="0.001 0.001 0.001"/>
      </geometry>
      <material name="blue"/>
    </visual>
    <collision>
      <origin rpy="-1.5708 0.0 1.5708" xyz="0.0 -0.1 0.1"/>
      <geometry>
        <mesh filename="file:///home/ros/eb65_ws/src/eb65_description/meshes/029_simplified.stl" scale="0.001 0.001 0.001"/>
      </geometry>
    </collision>
    <inertial>
      <origin rpy="0 0 0" xyz="0 0 0"/>
      <mass value="0.08"/>
      <inertia ixx="8e-5" ixy="0" ixz="0" iyy="8e-5" iyz="0" izz="8e-5"/>
    </inertial>
  </link>
  <link name="top_finger">
    <visual>
      <origin rpy="-1.5708 0.0 1.5708" xyz="0.0 -0.1 0.1"/>
      <geometry>
        <mesh filename="file:///home/ros/eb65_ws/src/eb65_description/meshes/031_simplified.stl" scale="0.001 0.001 0.001"/>
      </geometry>
      <material name="blue"/>
    </visual>
    <collision>
      <origin rpy="-1.5708 0.0 1.5708" xyz="0.0 -0.1 0.1"/>
      <geometry>
        <mesh filename="file:///home/ros/eb65_ws/src/eb65_description/meshes/031_simplified.stl" scale="0.001 0.001 0.001"/>
      </geometry>
    </collision>
    <inertial>
      <origin rpy="0 0 0" xyz="0 0 0"/>
      <mass value="0.08"/>
      <inertia ixx="8e-5" ixy="0" ixz="0" iyy="8e-5" iyz="0" izz="8e-5"/>
    </inertial>
  </link>
  <link name="gear_link">
    <visual>
      <origin rpy="0.0 1.5708 0.0" xyz="0.0 -0.1 0.1"/>
      <geometry>
        <mesh filename="file:///home/ros/eb65_ws/src/eb65_description/meshes/030_simplified.stl" scale="0.001 0.001 0.001"/>
      </geometry>
      <material name="blue"/>
    </visual>
    <collision>
      <origin rpy="0.0 1.5708 0.0" xyz="0.0 -0.1 0.1"/>
      <geometry>
        <mesh filename="file:///home/ros/eb65_ws/src/eb65_description/meshes/030_simplified.stl" scale="0.001 0.001 0.001"/>
      </geometry>
    </collision>
    <inertial>
      <origin rpy="0 0 0" xyz="0 0 0"/>
      <mass value="0.1"/>
      <inertia ixx="0.0001" ixy="0" ixz="0" iyy="0.0001" iyz="0" izz="0.0001"/>
    </inertial>
  </link>
  <link name="bottom_finger_support_link">
    <visual>
      <origin rpy="-1.5708 0.0 -1.5708" xyz="0.0 0.1 0.1"/>
      <geometry>
        <mesh filename="file:///home/ros/eb65_ws/src/eb65_description/meshes/032_simplified.stl" scale="0.001 0.001 0.001"/>
      </geometry>
      <material name="blue"/>
    </visual>
    <collision>
      <origin rpy="-1.5708 0.0 -1.5708" xyz="0.0 0.1 0.1"/>
      <geometry>
        <mesh filename="file:///home/ros/eb65_ws/src/eb65_description/meshes/032_simplified.stl" scale="0.001 0.001 0.001"/>
      </geometry>
    </collision>
    <inertial>
      <origin rpy="0 0 0" xyz="0 0 0"/>
      <mass value="0.05"/>
      <inertia ixx="5e-5" ixy="0" ixz="0" iyy="5e-5" iyz="0" izz="5e-5"/>
    </inertial>
  </link>
  <link name="bottom_finger_support_link_2">
    <visual>
      <origin rpy="-1.5708 0.0 -1.5708" xyz="0.0 0.1 0.1"/>
      <geometry>
        <mesh filename="file:///home/ros/eb65_ws/src/eb65_description/meshes/034_simplified.stl" scale="0.001 0.001 0.001"/>
      </geometry>
      <material name="blue"/>
    </visual>
    <collision>
      <origin rpy="-1.5708 0.0 -1.5708" xyz="0.0 0.1 0.1"/>
      <geometry>
        <mesh filename="file:///home/ros/eb65_ws/src/eb65_description/meshes/034_simplified.stl" scale="0.001 0.001 0.001"/>
      </geometry>
    </collision>
    <inertial>
      <origin rpy="0 0 0" xyz="0 0 0"/>
      <mass value="0.05"/>
      <inertia ixx="5e-5" ixy="0" ixz="0" iyy="5e-5" iyz="0" izz="5e-5"/>
    </inertial>
  </link>
  <link name="top_finger_support_link">
    <visual>
      <origin rpy="-1.5708 0.0 -1.5708" xyz="0.0 0.1 0.1"/>
      <geometry>
        <mesh filename="file:///home/ros/eb65_ws/src/eb65_description/meshes/035_simplified.stl" scale="0.001 0.001 0.001"/>
      </geometry>
      <material name="blue"/>
    </visual>
    <collision>
      <origin rpy="-1.5708 0.0 -1.5708" xyz="0.0 0.1 0.1"/>
      <geometry>
        <mesh filename="file:///home/ros/eb65_ws/src/eb65_description/meshes/035_simplified.stl" scale="0.001 0.001 0.001"/>
      </geometry>
    </collision>
    <inertial>
      <origin rpy="0 0 0" xyz="0 0 0"/>
      <mass value="0.05"/>
      <inertia ixx="5e-5" ixy="0" ixz="0" iyy="5e-5" iyz="0" izz="5e-5"/>
    </inertial>
  </link>
  <link name="top_finger_support_link_2">
    <visual>
      <origin rpy="-1.5708 0.0 -1.5708" xyz="0.0 0.1 0.1"/>
      <geometry>
        <mesh filename="file:///home/ros/eb65_ws/src/eb65_description/meshes/033_simplified.stl" scale="0.001 0.001 0.001"/>
      </geometry>
      <material name="blue"/>
    </visual>
    <collision>
      <origin rpy="-1.5708 0.0 -1.5708" xyz="0.0 0.1 0.1"/>
      <geometry>
        <mesh filename="file:///home/ros/eb65_ws/src/eb65_description/meshes/033_simplified.stl" scale="0.001 0.001 0.001"/>
      </geometry>
    </collision>
    <inertial>
      <origin rpy="0 0 0" xyz="0 0 0"/>
      <mass value="0.05"/>
      <inertia ixx="5e-5" ixy="0" ixz="0" iyy="5e-5" iyz="0" izz="5e-5"/>
    </inertial>
  </link>
  <!-- ==================== LOGO GROUP ==================== -->
  <link name="logo_link_1">
    <visual>
      <origin rpy="1.5708 0.0 0.0" xyz="-0.1 0.0 -0.1"/>
      <geometry>
        <mesh filename="file:///home/ros/eb65_ws/src/eb65_description/meshes/036_simplified.stl" scale="0.001 0.001 0.001"/>
      </geometry>
      <material name="blue"/>
    </visual>
    <collision>
      <origin rpy="1.5708 0.0 0.0" xyz="-0.1 0.0 -0.1"/>
      <geometry>
        <mesh filename="file:///home/ros/eb65_ws/src/eb65_description/meshes/036_simplified.stl" scale="0.001 0.001 0.001"/>
      </geometry>
    </collision>
    <inertial>
      <origin rpy="0 0 0" xyz="0 0 0"/>
      <mass value="0.01"/>
      <inertia ixx="1e-5" ixy="0" ixz="0" iyy="1e-5" iyz="0" izz="1e-5"/>
    </inertial>
  </link>
  <link name="logo_link_2">
    <visual>
      <origin rpy="-1.5708 0.0 0.0" xyz="-0.1 0.0 0.1"/>
      <geometry>
        <mesh filename="file:///home/ros/eb65_ws/src/eb65_description/meshes/036_simplified.stl" scale="0.001 0.001 0.001"/>
      </geometry>
      <material name="blue"/>
    </visual>
    <collision>
      <origin rpy="-1.5708 0.0 0.0" xyz="-0.1 0.0 0.1"/>
      <geometry>
        <mesh filename="file:///home/ros/eb65_ws/src/eb65_description/meshes/036_simplified.stl" scale="0.001 0.001 0.001"/>
      </geometry>
    </collision>
    <inertial>
      <origin rpy="0 0 0" xyz="0 0 0"/>
      <mass value="0.01"/>
      <inertia ixx="1e-5" ixy="0" ixz="0" iyy="1e-5" iyz="0" izz="1e-5"/>
    </inertial>
  </link>
  <link name="logo_link_3">
    <visual>
      <origin rpy="-1.5708 0.0 0.0" xyz="-0.1 0.0 0.1"/>
      <geometry>
        <mesh filename="file:///home/ros/eb65_ws/src/eb65_description/meshes/036_simplified.stl" scale="0.001 0.001 0.001"/>
      </geometry>
      <material name="white"/>
    </visual>
    <collision>
      <origin rpy="-1.5708 0.0 0.0" xyz="-0.1 0.0 0.1"/>
      <geometry>
        <mesh filename="file:///home/ros/eb65_ws/src/eb65_description/meshes/036_simplified.stl" scale="0.001 0.001 0.001"/>
      </geometry>
    </collision>
    <inertial>
      <origin rpy="0 0 0" xyz="0 0 0"/>
      <mass value="0.01"/>
      <inertia ixx="1e-5" ixy="0" ixz="0" iyy="1e-5" iyz="0" izz="1e-5"/>
    </inertial>
  </link>
  <link name="logo_link_4">
    <visual>
      <origin rpy="1.5708 0.0 0.0" xyz="-0.1 0.0 -0.1"/>
      <geometry>
        <mesh filename="file:///home/ros/eb65_ws/src/eb65_description/meshes/036_simplified.stl" scale="0.001 0.001 0.001"/>
      </geometry>
      <material name="white"/>
    </visual>
    <collision>
      <origin rpy="1.5708 0.0 0.0" xyz="-0.1 0.0 -0.1"/>
      <geometry>
        <mesh filename="file:///home/ros/eb65_ws/src/eb65_description/meshes/036_simplified.stl" scale="0.001 0.001 0.001"/>
      </geometry>
    </collision>
    <inertial>
      <origin rpy="0 0 0" xyz="0 0 0"/>
      <mass value="0.01"/>
      <inertia ixx="1e-5" ixy="0" ixz="0" iyy="1e-5" iyz="0" izz="1e-5"/>
    </inertial>
  </link>
  <!-- ==================== JOINTS ==================== -->
  <joint name="base_joint" type="fixed">
    <origin rpy="0.0 0.0 0.0" xyz="0.0 0.0 0.0"/>
    <parent link="base_footprint"/>
    <child link="base_link"/>
  </joint>
  <joint name="base_rotation_joint" type="revolute">
    <origin rpy="0.0 0.0 0.0" xyz="0.0 0.0 0.13"/>
    <parent link="base_link"/>
    <child link="base_rotation_link"/>
    <axis xyz="0.0 0.0 1.0"/>
    <limit effort="10.0" lower="-3.14" upper="3.14" velocity="5.0"/>
  </joint>
  <joint name="base_joint_1" type="fixed">
    <origin rpy="0.0 0.0 0.0" xyz="0.0 0.0 0.0"/>
    <parent link="base_rotation_link"/>
    <child link="base_link_3"/>
  </joint>
  <joint name="base_joint_2" type="fixed">
    <origin rpy="0.0 0.0 0.0" xyz="0.0 -0.06 0.0"/>
    <parent link="base_rotation_link"/>
    <child link="base_link_4"/>
  </joint>
  <joint name="base_joint_3" type="fixed">
    <origin rpy="0.0 0.0 0.0" xyz="0.0 0.06 0.0"/>
    <parent link="base_rotation_link"/>
    <child link="base_link_5"/>
  </joint>
  <joint name="shoulder_right_joint" type="revolute">
    <origin rpy="0.0 0.0 0.0" xyz="0.015 0.015 0.1"/>
    <parent link="base_link_4"/>
    <child link="shoulder_right_link"/>
    <axis xyz="0.0 1.0 0.0"/>
    <limit effort="5.0" lower="-1.57" upper="1.57" velocity="3.0"/>
  </joint>
  <joint name="shoulder_right_joint_1" type="fixed">
    <origin rpy="0.0 0.0 0.0" xyz="-0.0125 0.02 0.095"/>
    <parent link="shoulder_right_link"/>
    <child link="shoulder_right_link_1"/>
  </joint>
  <joint name="shoulder_right_joint_2" type="fixed">
    <origin rpy="0.0 0.0 0.0" xyz="0.0 -0.008 0.1"/>
    <parent link="shoulder_right_link_1"/>
    <child link="shoulder_right_link_2"/>
  </joint>
  <joint name="shoulder_left_joint" type="fixed">
    <origin rpy="0.0 0.0 0.0" xyz="0.0 0.09 0.0"/>
    <parent link="shoulder_right_link"/>
    <child link="shoulder_left_link"/>
  </joint>
  <joint name="shoulder_left_joint_1" type="fixed">
    <origin rpy="0.0 0.0 0.0" xyz="-0.0125 -0.04 0.095"/>
    <parent link="shoulder_left_link"/>
    <child link="shoulder_left_link_1"/>
  </joint>
  <joint name="shoulder_left_joint_2" type="fixed">
    <origin rpy="0.0 0.0 0.0" xyz="0.01 0.02 0.1"/>
    <parent link="shoulder_left_link_1"/>
    <child link="shoulder_left_link_2"/>
  </joint>
  <joint name="elbow_joint" type="revolute">
    <origin rpy="0.0 0.0 0.0" xyz="0.005 0.03 0.12"/>
    <parent link="shoulder_right_link_2"/>
    <child link="elbow_link"/>
    <axis xyz="0.0 1.0 0.0"/>
    <limit effort="5.0" lower="-1.57" upper="1.57" velocity="3.0"/>
  </joint>
  <joint name="elbow_support_joint" type="fixed">
    <origin rpy="0.0 0.0 0.0" xyz="0.07 0.0 0.039"/>
    <parent link="elbow_link"/>
    <child link="elbow_support_link"/>
  </joint>
  <joint name="elbow_rotation_joint" type="revolute">
    <origin rpy="0.0 0.0 0.0" xyz="0.06 0.0 0.008"/>
    <parent link="elbow_support_link"/>
    <child link="elbow_rotation_link"/>
    <axis xyz="1.0 0.0 0.0"/>
    <limit effort="5.0" lower="-1.57" upper="1.57" velocity="3.0"/>
  </joint>
  <joint name="support_joint_1" type="fixed">
    <origin rpy="0.0 0.0 0.0" xyz="0.0 0.0 -0.045"/>
    <parent link="elbow_rotation_link"/>
    <child link="support_link_1"/>
  </joint>
  <joint name="support_joint_2" type="fixed">
    <origin rpy="0.0 0.0 0.0" xyz="0.005 0.0 0.02"/>
    <parent link="elbow_rotation_link"/>
    <child link="support_link_2"/>
  </joint>
  <joint name="support_joint_3" type="fixed">
    <origin rpy="0.0 0.0 0.0" xyz="0.154 0.0 -0.004"/>
    <parent link="elbow_rotation_link"/>
    <child link="support_link_3"/>
  </joint>
  <joint name="wrist_joint" type="revolute">
    <origin rpy="0.0 0.0 0.0" xyz="0.05 -0.003 -0.002"/>
    <parent link="support_link_3"/>
    <child link="wrist_link"/>
    <axis xyz="0.0 1.0 0.0"/>
    <limit effort="5.0" lower="-1.57" upper="1.57" velocity="3.0"/>
  </joint>
  <joint name="support_joint_4" type="fixed">
    <origin rpy="0.0 0.0 0.0" xyz="0.08 -0.034 -0.005"/>
    <parent link="elbow_rotation_link"/>
    <child link="support_link_4"/>
  </joint>
  <joint name="support_joint_5" type="fixed">
    <origin rpy="0.0 0.0 0.0" xyz="0.08 0.034 -0.005"/>
    <parent link="elbow_rotation_link"/>
    <child link="support_link_5"/>
  </joint>
  <joint name="support_joint_6" type="fixed">
    <origin rpy="0.0 0.0 0.0" xyz="0.04 -0.035 -0.005"/>
    <parent link="elbow_rotation_link"/>
    <child link="support_link_6"/>
  </joint>
  <joint name="support_joint_7" type="fixed">
    <origin rpy="0.0 0.0 0.0" xyz="0.04 0.035 -0.005"/>
    <parent link="elbow_rotation_link"/>
    <child link="support_link_7"/>
  </joint>
  <joint name="support_joint_8" type="fixed">
    <origin rpy="0.0 0.0 0.0" xyz="0.0 0.025 0.01"/>
    <parent link="shoulder_right_link_1"/>
    <child link="support_link_8"/>
  </joint>
  <joint name="support_joint_9" type="fixed">
    <origin rpy="0.0 0.0 0.0" xyz="0.0 -0.042 -0.055"/>
    <parent link="shoulder_left_link"/>
    <child link="support_link_9"/>
  </joint>
  <joint name="support_joint_10" type="fixed">
    <origin rpy="0.0 0.0 0.0" xyz="-0.012 -0.025 0.04"/>
    <parent link="shoulder_left_link_2"/>
    <child link="support_link_10"/>
  </joint>
  <joint name="gear_joint" type="revolute">
    <origin rpy="0.0 0.0 0.0" xyz="0.04 0.0 -0.005"/>
    <parent link="wrist_link"/>
    <child link="gripper_rotation_link"/>
    <axis xyz="1.0 0.0 0.0"/>
    <limit effort="5.0" lower="-1.57" upper="1.57" velocity="3.0"/>
  </joint>
  <joint name="gripper_support_joint_1" type="fixed">
    <origin rpy="0.0 0.0 0.0" xyz="0.05 0.005 0.0"/>
    <parent link="gripper_rotation_link"/>
    <child link="gripper_support_link"/>
  </joint>
  <joint name="gripper_support_joint_2" type="fixed">
    <origin rpy="0.0 0.0 0.0" xyz="0.0 0.0 0.0"/>
    <parent link="gripper_support_link"/>
    <child link="gripper_support_link_2"/>
  </joint>
  <joint name="gripper_joint" type="revolute">
    <origin rpy="0.0 0.0 0.0" xyz="0.008 0.0 0.0"/>
    <parent link="gripper_support_link_2"/>
    <child link="gear_link"/>
    <axis xyz="1.0 0.0 0.0"/>
    <limit effort="2.0" lower="-0.55" upper="0.8" velocity="2.0"/>
  </joint>
  <joint name="bottom_prismatic" type="prismatic">
    <origin rpy="0.0 0.0 0.0" xyz="0.015 0.0 -0.013"/>
    <parent link="gripper_support_link_2"/>
    <child link="bottom_finger"/>
    <axis xyz="0.0 1.0 0.0"/>
    <limit effort="2.0" lower="-0.016" upper="0.016" velocity="1.0"/>
    <mimic joint="gripper_joint" multiplier="0.02" offset="0"/>
  </joint>
  <joint name="top_prismatic" type="prismatic">
    <origin rpy="0.0 0.0 0.0" xyz="0.015 0.0 0.013"/>
    <parent link="gripper_support_link_2"/>
    <child link="top_finger"/>
    <axis xyz="0.0 -1.0 0.0"/>
    <limit effort="2.0" lower="-0.016" upper="0.016" velocity="1.0"/>
    <mimic joint="gripper_joint" multiplier="0.02" offset="0"/>
  </joint>
  <joint name="bottom_finger_support_joint_1" type="fixed">
    <origin rpy="0.0 0.0 0.0" xyz="0.002 0.02 0.01"/>
    <parent link="bottom_finger"/>
    <child link="bottom_finger_support_link"/>
  </joint>
  <joint name="bottom_finger_support_joint_2" type="fixed">
    <origin rpy="0.0 0.0 0.0" xyz="0.01 0.0 0.005"/>
    <parent link="bottom_finger_support_link"/>
    <child link="bottom_finger_support_link_2"/>
  </joint>
  <joint name="top_finger_support_joint_1" type="fixed">
    <origin rpy="0.0 0.0 0.0" xyz="0.002 -0.02 -0.01"/>
    <parent link="top_finger"/>
    <child link="top_finger_support_link"/>
  </joint>
  <joint name="top_finger_support_joint_2" type="fixed">
    <origin rpy="0.0 0.0 0.0" xyz="0.01 0.0 -0.0025"/>
    <parent link="top_finger_support_link"/>
    <child link="top_finger_support_link_2"/>
  </joint>
  <joint name="logo_joint_1" type="fixed">
    <origin rpy="0.0 0.0 0.0" xyz="0.0 -0.105 0.135"/>
    <parent link="shoulder_left_link_2"/>
    <child link="logo_link_1"/>
  </joint>
  <joint name="logo_joint_2" type="fixed">
    <origin rpy="0.0 0.0 0.0" xyz="0.0 0.05 0.135"/>
    <parent link="shoulder_left_link_2"/>
    <child link="logo_link_2"/>
  </joint>
  <joint name="logo_joint_3" type="fixed">
    <origin rpy="0.0 0.0 0.0" xyz="0.0 0.027 -0.005"/>
    <parent link="shoulder_left_link"/>
    <child link="logo_link_3"/>
  </joint>
  <joint name="logo_joint_4" type="fixed">
    <origin rpy="0.0 0.0 0.0" xyz="0.0 -0.115 -0.005"/>
    <parent link="shoulder_left_link"/>
    <child link="logo_link_4"/>
  </joint>
  <gazebo>
    <plugin filename="gz_ros2_control-system" name="gz_ros2_control::GazeboSimROS2ControlPlugin">
      <parameters>/home/ros/eb65_ws/install/eb65_description/share/eb65_description/config/eb65_controller.yaml</parameters>
    </plugin>
  </gazebo>
  <ros2_control name="RobotController" type="system">
    <hardware>
      <plugin>gz_ros2_control/GazeboSimSystem</plugin>
    </hardware>
    <joint name="base_rotation_joint">
      <command_interface name="position"/>
      <state_interface name="position"/>
      <state_interface name="velocity"/>
      <state_interface name="effort"/>
    </joint>
    <joint name="shoulder_right_joint">
      <command_interface name="position"/>
      <state_interface name="position"/>
      <state_interface name="velocity"/>
      <state_interface name="effort"/>
    </joint>
    <joint name="elbow_joint">
      <command_interface name="position"/>
      <state_interface name="position"/>
      <state_interface name="velocity"/>
      <state_interface name="effort"/>
    </joint>
    <joint name="elbow_rotation_joint">
      <command_interface name="position"/>
      <state_interface name="position"/>
      <state_interface name="velocity"/>
      <state_interface name="effort"/>
    </joint>
    <joint name="wrist_joint">
      <command_interface name="position"/>
      <state_interface name="position"/>
      <state_interface name="velocity"/>
      <state_interface name="effort"/>
    </joint>
    <joint name="gear_joint">
      <command_interface name="position"/>
      <state_interface name="position"/>
      <state_interface name="velocity"/>
      <state_interface name="effort"/>
    </joint>
    <joint name="gripper_joint">
      <command_interface name="position"/>
      <state_interface name="position"/>
      <state_interface name="velocity"/>
      <state_interface name="effort"/>
    </joint>
  </ros2_control>
</robot>
